<?xml version="1.0"?>
<robot name="baker_gripper" xmlns:xacro="http://www.ros.org/wiki/xacro">

  <xacro:include filename="$(find cob_description)/urdf/common.xacro" />
  <xacro:include filename="$(find cob_description)/urdf/baker_gripper/baker_two_fingure_gripper.transmission.xacro" />
  <xacro:include filename="$(find cob_description)/urdf/baker_gripper/baker.gazebo.xacro" />

    <xacro:macro name="baker_gripper" params="prefix parent *origin">

        <joint name="${prefix}gripper_base_joint" type="fixed">
            <parent link="${parent}"/>
            <child link="${prefix}gripper_base_link"/>
            <xacro:insert_block name="origin"/>
        </joint>
        <link name="${prefix}gripper_base_link">
        <visual>
            <xacro:sphere_geometry radius="0.00001"/>
            <material name="IPA/LightGrey" />
        </visual>
        <collision>
            <xacro:sphere_geometry radius="0.000001"/>
        </collision>
        </link>

        <!--link name="${prefix}gripper_base_link">
            <visual>
                <geometry>
                    <mesh filename="package://cob_description/meshes/baker_arm/Gripper_red2.STL"/>
                </geometry>
            </visual>
            <collision>
                <geometry>
                    <mesh filename="package://cob_description/meshes/baker_arm/Gripper_red2.STL"/>
                </geometry>
            </collision>
            <xacro:default_inertial/>
        </link-->

        <!--gazebo reference="${prefix}gripper_base_link">
            <implicitSpringDamper>1</implicitSpringDamper>
            <mu1>100000</mu1>
            <mu2>100000</mu2>
            <kp>100000000.0</kp>
            <kd>1.0</kd>
        </gazebo-->

        <joint name="${prefix}gripper_finger1_joint" type="prismatic"> <!-- left part -->
            <parent link="${prefix}gripper_base_link"/>
            <child link="${prefix}gripper_finger1_knuckle_link"/>
            <axis xyz="0 0 1"/>
            <!--origin xyz="-0.05 0.06 0.065 " rpy="-${M_PI/2} 0 -${M_PI/2}"/-->
            <origin xyz="-0.01 0 0.105" rpy="0 ${M_PI/2} ${M_PI}"/>
            <limit effort="500" velocity="0.02" lower="-0.25" upper="0.1" />
            <axis xyz="0 0 1"/>
        </joint>

        <joint name="${prefix}gripper_finger2_joint" type="prismatic"> <!-- right part -->
            <parent link="${prefix}gripper_base_link"/>
            <child link="${prefix}gripper_finger2_knuckle_link"/>
            <axis xyz="0 0 1"/>
            <!--origin xyz="0.05 0.06 0.065 " rpy="-${M_PI/2} ${M_PI} ${M_PI/2}"/-->
            <origin xyz="0.01 0 0.105" rpy="-${M_PI} ${M_PI/2} -${M_PI}"/>
            <limit lower="-0.25" upper="1.0" velocity="0.02" effort="500"/>
            <mimic joint="${prefix}gripper_finger1_joint"/>
        </joint>

        <link name="${prefix}gripper_finger1_knuckle_link">
            <visual>
                <geometry>
                    <mesh filename="package://cob_description/meshes/baker_arm/Bigfinger_left_red2.STL"/>
                </geometry>
                <material name="IPA/LightGrey"/>
            </visual>
            <collision>
                <geometry>
                    <mesh filename="package://cob_description/meshes/baker_arm/Bigfinger_left_red2.STL"/>
                </geometry>
            </collision>
            <!--inertial>
                <mass value="0.018491" />
                <origin xyz="0.0 0.0 0.0" />
                <inertia ixx = "0.000009" ixy = "-0.000001" ixz = "0.000000"
                         iyx = "-0.000001" iyy = "0.000001" iyz = "0.000000"
                         izx = "0.000000" izy = "0.000000" izz = "0.000010" />
            </inertial-->
            <xacro:default_inertial/>
        </link>

        <!--gazebo reference="${prefix}gripper_finger1_knuckle_link">
            <implicitSpringDamper>1</implicitSpringDamper>
            <mu1>100000</mu1>
            <mu2>100000</mu2>
            <kp>100000000.0</kp>
            <kd>1.0</kd>
        </gazebo-->

        <link name="${prefix}gripper_finger2_knuckle_link">
            <visual>
                <geometry>
                    <mesh filename="package://cob_description/meshes/baker_arm/Bigfinger_left_red2.STL"/>
                </geometry>
                <material name="IPA/LightGrey"/>
            </visual>
            <collision>
                <geometry>
                    <mesh filename="package://cob_description/meshes/baker_arm/Bigfinger_left_red2.STL"/>
                </geometry>
            </collision>
            <!--inertial>
                <mass value="0.018491" />
                <origin xyz="0.0 0.0 0.0" />
                <inertia ixx = "0.000009" ixy = "-0.000001" ixz = "0.000000"
                         iyx = "-0.000001" iyy = "0.000001" iyz = "0.000000"
                         izx = "0.000000" izy = "0.000000" izz = "0.000010" />
            </inertial-->
            <xacro:default_inertial/>
        </link>

        <!--gazebo reference="${prefix}gripper_finger2_knuckle_link">
            <implicitSpringDamper>1</implicitSpringDamper>
            <mu1>100000</mu1>
            <mu2>100000</mu2>
            <kp>100000000.0</kp>
            <kd>1.0</kd>
        </gazebo-->

        <joint name="${prefix}gripper_finger1_finger_joint" type="revolute">
            <parent link="${prefix}gripper_finger1_knuckle_link"/>
            <child link="${prefix}gripper_finger1_finger_link"/>
            <origin xyz="-0.07 0.015 0.005" rpy="0 0 0"/>
            <limit effort="500" velocity="0.5" lower="-2.0" upper="0" />
        </joint>

        <joint name="${prefix}gripper_finger2_finger_joint" type="revolute">
            <parent link="${prefix}gripper_finger2_knuckle_link"/>
            <child link="${prefix}gripper_finger2_finger_link"/>
            <origin xyz="-0.07 0.015 0.005" rpy="0 0 0"/>
            <limit effort="500" velocity="0.5" lower="-2.0" upper="0" />
            <mimic joint="${prefix}gripper_finger1_finger_joint"/>
        </joint>

        <link name="${prefix}gripper_finger1_finger_link">
            <visual>
                <geometry>
                    <mesh filename="package://cob_description/meshes/baker_arm/Smallfinger_red2.STL"/>
                </geometry>
                <material name="IPA/LightGrey"/>
            </visual>
            <collision>
                <geometry>
                    <mesh filename="package://cob_description/meshes/baker_arm/Smallfinger_red2.STL"/>
                </geometry>
            </collision>
            <!--inertial>
                <mass value="0.027309" />
                <origin xyz="0.0 0.0 0.0" />
                <inertia ixx = "0.000003" ixy = "-0.000002" ixz = "0.000000"
                         iyx = "-0.000002" iyy = "0.000021" iyz = "0.000000"
                         izx = "0.000000" izy = "0.000000" izz = "0.000020" />
            </inertial-->
            <xacro:default_inertial/>
        </link>

        <!--gazebo reference="${prefix}gripper_finger1_finger_link">
            <implicitSpringDamper>1</implicitSpringDamper>
            <mu1>100000</mu1>
            <mu2>100000</mu2>
            <kp>100000000.0</kp>
            <kd>1.0</kd>
        </gazebo-->

        <link name="${prefix}gripper_finger2_finger_link">
            <visual>
                <geometry>
                    <mesh filename="package://cob_description/meshes/baker_arm/Smallfinger_red2.STL"/>
                </geometry>
                <material name="IPA/LightGrey"/>
            </visual>
            <collision>
                <geometry>
                    <mesh filename="package://cob_description/meshes/baker_arm/Smallfinger_red2.STL"/>
                </geometry>
            </collision>
            <!--inertial>
                <mass value="0.027309" />
                <origin xyz="0.0 0.0 0.0" />
                <inertia ixx = "0.000003" ixy = "-0.000002" ixz = "0.000000"
                         iyx = "-0.000002" iyy = "0.000021" iyz = "0.000000"
                         izx = "0.000000" izy = "0.000000" izz = "0.000020" />
            </inertial-->
            <xacro:default_inertial/>
        </link>
     <!--
        <gazebo reference="${prefix}gripper_finger2_finger_link">
            <implicitSpringDamper>1</implicitSpringDamper>
            <mu1>100000</mu1>
            <mu2>100000</mu2>
            <kp>100000000.0</kp>
            <kd>1.0</kd>
        </gazebo>
        -->
    <!--
        <joint name="${prefix}gripper_finger1_inner_knuckle_joint" type="continuous">
            <parent link="${prefix}gripper_base_link"/>
            <child link="${prefix}gripper_finger1_inner_knuckle_link"/>
            <axis xyz="0 0 1"/>
            <origin xyz="0.06142 0.0127 0" rpy="${pi} 0.0 0.0" />
            <limit lower="-3.14" upper="3.14" velocity="100.0" effort="0.1"/>
            <mimic joint="${prefix}gripper_finger1_joint" offset="0"/>
        </joint>

        <joint name="${prefix}gripper_finger2_inner_knuckle_joint" type="continuous">
            <parent link="${prefix}gripper_base_link"/>
            <child link="${prefix}gripper_finger2_inner_knuckle_link"/>
            <axis xyz="0 0 1"/>
            <origin xyz="0.06142 -0.0127 0" rpy="0 0 0"/>
            <limit lower="-3.14" upper="3.14" velocity="100.0" effort="0.1"/>
            <mimic joint="${prefix}gripper_finger1_joint" offset="0"/>
        </joint>

        <link name="${prefix}gripper_finger1_inner_knuckle_link">
            <visual>
                <geometry>
                    <mesh filename="package://robotiq_85_description/meshes/visual/robotiq_85_inner_knuckle_link.dae"/>
                </geometry>
            </visual>
            <collision>
                <geometry>
                    <mesh filename="package://robotiq_85_description/meshes/collision/robotiq_85_inner_knuckle_link.stl"/>
                </geometry>
            </collision>
            <inertial>
                <mass value="0.029951" />
                <origin xyz="0.0 0.0 0.0" />
                <inertia ixx = "0.000039" ixy = "0.000000" ixz = "0.000000"
                         iyx = "0.000000" iyy = "0.000005" iyz = "0.000000"
                         izx = "0.000000" izy = "0.000000" izz = "0.000035" />
            </inertial>
        </link>

        <gazebo reference="${prefix}gripper_finger1_inner_knuckle_link">
            <implicitSpringDamper>1</implicitSpringDamper>
            <mu1>100000</mu1>
            <mu2>100000</mu2>
            <kp>100000000.0</kp>
            <kd>1.0</kd>
        </gazebo>

        <link name="${prefix}gripper_finger2_inner_knuckle_link">
            <visual>
                <geometry>
                    <mesh filename="package://robotiq_85_description/meshes/visual/robotiq_85_inner_knuckle_link.dae"/>
                </geometry>
            </visual>
            <collision>
                <geometry>
                    <mesh filename="package://robotiq_85_description/meshes/collision/robotiq_85_inner_knuckle_link.stl"/>
                </geometry>
            </collision>
            <inertial>
                <mass value="0.029951" />
                <origin xyz="0.0 0.0 0.0" />
                <inertia ixx = "0.000039" ixy = "0.000000" ixz = "0.000000"
                         iyx = "0.000000" iyy = "0.000005" iyz = "0.000000"
                         izx = "0.000000" izy = "0.000000" izz = "0.000035" />
            </inertial>
        </link>

        <gazebo reference="${prefix}gripper_finger2_inner_knuckle_link">
            <implicitSpringDamper>1</implicitSpringDamper>
            <mu1>100000</mu1>
            <mu2>100000</mu2>
            <kp>100000000.0</kp>
            <kd>1.0</kd>
        </gazebo>

        <joint name="${prefix}gripper_finger1_finger_tip_joint" type="continuous">
            <parent link="${prefix}gripper_finger1_inner_knuckle_link"/>
            <child link="${prefix}gripper_finger1_finger_tip_link"/>
            <axis xyz="0 0 1"/>
            <origin xyz="0.04303959807 -0.03759940821 0.0" rpy="0.0 0.0 0.0"/>
            <limit lower="-3.14" upper="3.14" velocity="100.0" effort="0.1"/>
            <mimic joint="${prefix}gripper_finger1_joint" multiplier="-1"/>
        </joint>

        <joint name="${prefix}gripper_finger2_finger_tip_joint" type="continuous">
            <parent link="${prefix}gripper_finger2_inner_knuckle_link"/>
            <child link="${prefix}gripper_finger2_finger_tip_link"/>
            <axis xyz="0 0 1"/>
            <origin rpy="0.0 0.0 0.0" xyz="0.04303959807 -0.03759940821  0.0"/>
            <limit lower="-3.14" upper="3.14" velocity="100.0" effort="0.1"/>
            <mimic joint="${prefix}gripper_finger1_joint" multiplier="-1"/>
        </joint>


        <link name="${prefix}gripper_finger1_finger_tip_link">
            <visual>
                <geometry>
                    <mesh filename="package://robotiq_85_description/meshes/visual/robotiq_85_finger_tip_link.dae"/>
                </geometry>
            </visual>
            <collision>
                <geometry>
                    <mesh filename="package://robotiq_85_description/meshes/collision/robotiq_85_finger_tip_link.stl"/>
                </geometry>
            </collision>
            <inertial>
                <mass value="0.019555" />
                <origin xyz="0.0 0.0 0.0" />
                <inertia ixx = "0.000002" ixy = "0.000000" ixz = "0.000000"
                         iyx = "0.000000" iyy = "0.000005" iyz = "0.000000"
                         izx = "0.000000" izy = "0.000000" izz = "0.000006" />
            </inertial>
        </link>

        <gazebo reference="${prefix}gripper_finger1_finger_tip_link">
            <implicitSpringDamper>1</implicitSpringDamper>
            <mu1>100000</mu1>
            <mu2>100000</mu2>
            <kp>100000000.0</kp>
            <kd>1.0</kd>
        </gazebo>

        <link name="${prefix}gripper_finger2_finger_tip_link">
            <visual>
                <geometry>
                    <mesh filename="package://robotiq_85_description/meshes/visual/robotiq_85_finger_tip_link.dae"/>
                </geometry>
            </visual>
            <collision>
                <geometry>
                    <mesh filename="package://robotiq_85_description/meshes/collision/robotiq_85_finger_tip_link.stl"/>
                </geometry>
            </collision>
            <inertial>
                <mass value="0.019555" />
                <origin xyz="0.0 0.0 0.0" />
                <inertia ixx = "0.000002" ixy = "0.000000" ixz = "0.000000"
                         iyx = "0.000000" iyy = "0.000005" iyz = "0.000000"
                         izx = "0.000000" izy = "0.000000" izz = "0.000006" />
            </inertial>
        </link>

        <gazebo reference="${prefix}gripper_finger2_finger_tip_link">
            <implicitSpringDamper>1</implicitSpringDamper>
            <mu1>100000</mu1>
            <mu2>100000</mu2>
            <kp>100000000.0</kp>
            <kd>1.0</kd>
        </gazebo>
-->
    <joint name="gripper_to_tcp" type="fixed">
        <parent link="${prefix}gripper_base_link"/>
        <child link="gripper"/>
        <origin xyz="0.0 0.0 0.185" rpy="-1.57 -1.57 3.14"/> # 0.175
    </joint>

    <link name="gripper">
    <visual>
        <xacro:sphere_geometry radius="0.01"/>
        <material name="IPA/LightGrey" />
    </visual>
    <collision>
        <xacro:sphere_geometry radius="0.01"/>
    </collision>
    </link>

    <xacro:baker_gripper_transmission prefix="${prefix}" />
    <xacro:baker_gripper_gazebo prefix="${prefix}" />

    <!-- ros_control plugin -->
    <!--gazebo>
      <plugin name="ros_control" filename="libhwi_switch_gazebo_ros_control.so">
        <robotNamespace>${name}</robotNamespace>
        <filterJointsParam>joint_names</filterJointsParam>
      </plugin>
    </gazebo-->

  </xacro:macro>

</robot>
